I'm sorry, but an uncaught exception occurred.

While running game code:
  File "game/chapters/prologue2.rpy", line 129, in script
    nobruo "We definitely need to keep that momentum going!"
Exception: Sayer 'nobruo' is not defined.

-- Full Traceback ------------------------------------------------------------

Full traceback:
  File "game/chapters/prologue2.rpy", line 129, in script
    nobruo "We definitely need to keep that momentum going!"
  File "C:\Users\Brandon H\Desktop\renpy-8.2.1-sdk\renpy\ast.py", line 2557, in execute
    Say.execute(self)
  File "C:\Users\Brandon H\Desktop\renpy-8.2.1-sdk\renpy\ast.py", line 575, in execute
    who = eval_who(self.who, self.who_fast)
  File "C:\Users\Brandon H\Desktop\renpy-8.2.1-sdk\renpy\ast.py", line 464, in eval_who
    raise Exception("Sayer '%s' is not defined." % who)
Exception: Sayer 'nobruo' is not defined.

Windows-10-10.0.19045 AMD64
Ren'Py 8.2.1.24030407
Reawakening 1.0
Sat Jun 22 21:19:13 2024
